Traceback (most recent call last):
  File "C:\Users\ASUS\anaconda3\Lib\site-packages\jupyter_cache\executors\utils.py", line 58, in single_nb_execution
    executenb(
  File "C:\Users\ASUS\anaconda3\Lib\site-packages\nbclient\client.py", line 1305, in execute
    return NotebookClient(nb=nb, resources=resources, km=km, **kwargs).execute()
           ^^^^^^^^^^^^^^^^^^^^^^^^^^^^^^^^^^^^^^^^^^^^^^^^^^^^^^^^^^^^^^^^^^^^^
  File "C:\Users\ASUS\anaconda3\Lib\site-packages\jupyter_core\utils\__init__.py", line 165, in wrapped
    return loop.run_until_complete(inner)
           ^^^^^^^^^^^^^^^^^^^^^^^^^^^^^^
  File "C:\Users\ASUS\anaconda3\Lib\asyncio\base_events.py", line 687, in run_until_complete
    return future.result()
           ^^^^^^^^^^^^^^^
  File "C:\Users\ASUS\anaconda3\Lib\site-packages\nbclient\client.py", line 705, in async_execute
    await self.async_execute_cell(
  File "C:\Users\ASUS\anaconda3\Lib\site-packages\nbclient\client.py", line 1058, in async_execute_cell
    await self._check_raise_for_error(cell, cell_index, exec_reply)
  File "C:\Users\ASUS\anaconda3\Lib\site-packages\nbclient\client.py", line 914, in _check_raise_for_error
    raise CellExecutionError.from_cell_and_msg(cell, exec_reply_content)
nbclient.exceptions.CellExecutionError: An error occurred while executing the following cell:
------------------
import os
import pandas as pd
import numpy as np
import matplotlib.pyplot as plt
import seaborn as sns
from statsmodels.tsa.stattools import adfuller, acf, pacf
from statsmodels.tsa.seasonal import seasonal_decompose  # ImportaciÃ³n corregida
from statsmodels.graphics.tsaplots import plot_acf, plot_pacf
from sklearn.model_selection import train_test_split
from sklearn.preprocessing import StandardScaler
from sklearn.neighbors import KNeighborsClassifier
from sklearn.model_selection import GridSearchCV
from sklearn.naive_bayes import GaussianNB
from sklearn.tree import DecisionTreeClassifier
from sklearn.linear_model import RidgeClassifier, Lasso
from sklearn.linear_model import LogisticRegression
from sklearn.ensemble import RandomForestClassifier
import xgboost as xgb
import lime
import lime.lime_tabular
from sklearn.svm import SVC
from sklearn.neighbors import KNeighborsClassifier
from sklearn.neighbors import KDTree, BallTree
import faiss
import time
from sklearn.metrics import accuracy_score, precision_score, recall_score, f1_score
import pandas as pd


------------------


[1;31m---------------------------------------------------------------------------[0m
[1;31mModuleNotFoundError[0m                       Traceback (most recent call last)
Cell [1;32mIn[2], line 19[0m
[0;32m     17[0m [38;5;28;01mfrom[39;00m [38;5;21;01msklearn[39;00m[38;5;21;01m.[39;00m[38;5;21;01mensemble[39;00m [38;5;28;01mimport[39;00m RandomForestClassifier
[0;32m     18[0m [38;5;28;01mimport[39;00m [38;5;21;01mxgboost[39;00m [38;5;28;01mas[39;00m [38;5;21;01mxgb[39;00m
[1;32m---> 19[0m [38;5;28;01mimport[39;00m [38;5;21;01mlime[39;00m
[0;32m     20[0m [38;5;28;01mimport[39;00m [38;5;21;01mlime[39;00m[38;5;21;01m.[39;00m[38;5;21;01mlime_tabular[39;00m
[0;32m     21[0m [38;5;28;01mfrom[39;00m [38;5;21;01msklearn[39;00m[38;5;21;01m.[39;00m[38;5;21;01msvm[39;00m [38;5;28;01mimport[39;00m SVC

[1;31mModuleNotFoundError[0m: No module named 'lime'

